Workbook

Sheet 0. Capa
B2: Rota 2 de Julho (BR-116 e BR-324/BA): quanto vale ganhar esse leilão?
B4: Pergunta | C4: Qual o maior desconto na tarifa teto que um investidor de equity pode oferecer e ainda atingir o retorno exigido?
B5: Leilão | C5: 18/12/2026 (B3)
B6: Base | C6: Modelo econômico-financeiro do governo (MEF V4, 01/09/2026), valores reais da data-base, em R$ milhões
B7: Autora | C7: Maria Luísa Gama · out/2026
B8: Aviso | C8: Modelo de estudo com dados públicos; não é recomendação de investimento.
B10: Resultado principal | C10: ='1. Premissas'!B6 -> 0.25286888 | D10: desconto máximo com hurdle de 12% real (cenário base)
C11: ='9. Checagens'!C10 -> TRUE | D11: checagens do modelo
B12: Convenção de cores
C13: 1.234 | D13: Número digitado (entrada ou dado do MEF)
C14: 1.234 | D14: Fórmula
C15: 1.234 | D15: Link para outra aba
C16: 1.234 | D16: Resultado-chave
B18: Abas
C19: 1. Premissas | D19: Todas as entradas do modelo, com fonte, e a tabela de sensibilidade viva
C20: 2. Cenários | D20: Seletor base / pessimista / otimista
C21: Dados_MEF | D21: Séries anuais copiadas do modelo do governo (não mexer)
C22: 3. Receita | D22: Receita com o desconto do lance
C23: 4. Custos | D23: Opex e capex
C24: 5. Caixa | D24: EBITDA, impostos e caixa disponível para a dívida
C25: 6. Dívida | D25: Tamanho da dívida pelo ICSD e cronograma
C26: 7. Retornos | D26: TIR do projeto, TIR do acionista e desconto máximo
C27: 8. Sensibilidades | D27: TIR do acionista × desconto, por cenário (gráfico)
C28: 9. Checagens | D28: Testes que precisam dar zero / verdadeiro

Sheet 1. Premissas
A1: 1. Premissas
A2: Valores em termos reais (sem inflação), R$ milhões, na data-base do MEF. Células amarelas são entradas.
A4: Premissa | B4: Valor | C4: Unidade | D4: Fonte / comentário
A5: LEILÃO
A6: Desconto ofertado sobre a tarifa teto | B6: 0.25286888 | C6: % | D6: Variável de decisão. Começa em 0% para calibrar o modelo com o MEF
A7: Prazo da concessão | B7: 30 | C7: anos | D7: MEF, aba Resumo Fin.
A8: Tarifa teto pista simples (ano 1) | B8: 0.0839635 | C8: R$/km | D8: MEF, aba Resumo Fin.
A9: Tarifa teto pista dupla (ano 1) | B9: 0.113351 | C9: R$/km | D9: MEF, aba Resumo Fin.
A10: TIR de referência do governo (real) | B10: 0.1249 | C10: % | D10: MEF, aba WACC: TLP 7,55% + spread CR 2 de 4,94%
A11: TRIBUTOS E VERBAS
A12: Deduções sobre a receita bruta (ISS + PIS/COFINS) | B12: 0.0875 | C12: % | D12: Implícito no MEF (deduções ÷ receita bruta)
A13: IR + CSLL | B13: 0.34 | C13: % | D13: Lucro real
A14: Verbas vinculadas à receita | B14: 0.02 | C14: % | D14: MEF: recursos vinculados 1% + infraestrutura resiliente 1%
A15: DÍVIDA
A16: Custo real da dívida (acima do IPCA) | B16: 0.078 | C16: % a.a. | D16: A VERIFICAR: debêntures incentivadas / BNDES de infraestrutura em 2026
A17: ICSD mínimo exigido | B17: 1.3 | C17: x | D17: A VERIFICAR: referência usual de bancos e debenturistas
A18: Primeiro ano de amortização | B18: 9 | C18: ano | D18: Carência durante a obra pesada (anos 1 a 8)
A19: Último ano de amortização | B19: 24 | C19: ano | D19: Termina 6 anos antes do fim da concessão (folga, ou 'tail')
A20: Alavancagem máxima na construção | B20: 0.7 | C20: % do capex | D20: Bancos raramente financiam mais de 70% da obra
A21: ACIONISTA
A22: Retorno real exigido pelo equity (hurdle) | B22: 0.12 | C22: % a.a. | D22: A DEFINIR com você: acima do custo da dívida e da TIR do projeto?
A23: CENÁRIO
A24: Cenário ativo (1 = base, 2 = pessimista, 3 = otimista) | B24: 1 | D24: Escolhe a coluna da aba 2. Cenários
A26: TIR do acionista (resultado) | B26: ='7. Retornos'!C16 -> 0.12005201
A29: Sensibilidade: TIR do acionista (linhas = desconto, colunas = cenário)
B30: =B26 -> 0.12005201 | C30: 1 | D30: 2 | E30: 3
B31: 0 | C31: 0.43769205 | D31: 0.12904883 | E31: 0.65141422
B32: 0.05 | C32: 0.35644292 | D32: 0.10370182 | E32: 0.54652691
B33: 0.1 | C33: 0.28583102 | D33: 0.083937601 | E33: 0.44226504
B34: 0.15 | C34: 0.23389196 | D34: 0.067587585 | E34: 0.35624119
B35: 0.2 | C35: 0.17124676 | D35: 0.05325005 | E35: 0.28133646
B36: 0.25 | C36: 0.12221584 | D36: 0.04038261 | E36: 0.22538257
B37: 0.3 | C37: 0.090582167 | D37: 0.02862203 | E37: 0.18128439
B38: 0.35 | C38: 0.067269516 | D38: 0.017373489 | E38: 0.12086581
B39: 0.4 | C39: 0.048017359 | D39: 0.0063323551 | E39: 0.084026681

Sheet 2. Cenários
A1: 2. Cenários
A2: Cada linha tem um valor por cenário. A coluna 'Ativo' escolhe o valor conforme a célula de cenário da aba 1 (função ESCOLHER).
A4: Variável | B4: Base | C4: Pessimista | D4: Otimista | E4: Ativo | F4: Por quê
A5: Fator de tráfego (1 = estudo do governo) | B5: 1 | C5: 0.9 | D5: 1.05 | E5: =CHOOSE('1. Premissas'!$B$24,B5,C5,D5) -> 1 | F5: Pessimista: fuga e trecho urbano abaixo do estudo; otimista: crescimento acima
A6: Fator de capex (1 = orçamento do governo) | B6: 1 | C6: 1.15 | D6: 0.95 | E6: =CHOOSE('1. Premissas'!$B$24,B6,C6,D6) -> 1 | F6: Estouro de obra é o risco clássico de rodovia
A7: Fator de opex | B7: 1 | C7: 1.1 | D7: 0.95 | E7: =CHOOSE('1. Premissas'!$B$24,B7,C7,D7) -> 1
A8: Ajuste no custo da dívida (p.p.) | B8: 0 | C8: 0.01 | D8: -0.01 | E8: =CHOOSE('1. Premissas'!$B$24,B8,C8,D8) -> 0 | F8: Juros mudando entre o edital e o leilão

Sheet Dados_MEF
A1: Dados do MEF (modelo do governo, V4 de 01/09/2026)
A2: R$ milhões reais, data-base do MEF. Copiado das abas FS e CP. Não editar: as outras abas puxam daqui.
A3: Sinais: custos aparecem positivos. Capital de giro positivo = consome caixa.
A4: Ano da concessão | B4: Unidade | C4: Total | D4: 1 | E4: 2 | F4: 3 | G4: 4 | H4: 5 | I4: 6 | J4: 7 | K4: 8 | L4: 9 | M4: 10 | N4: 11 | O4: 12 | P4: 13 | Q4: 14 | R4: 15 | S4: 16 | T4: 17 | U4: 18 | V4: 19 | W4: 20 | X4: 21 | Y4: 22 | Z4: 23 | AA4: 24 | AB4: 25 | AC4: 26 | AD4: 27 | AE4: 28 | AF4: 29 | AG4: 30 | AI4: Fonte no MEF
A5: TRÁFEGO E TARIFA
A6: Veículos equivalentes nos 12 pórticos | B6: milhões/ano | C6: =SUM(D6:AG6) -> 7659.829 | D6: 111.192 | E6: 192.654 | F6: 194.02 | G6: 194.826 | H6: 198.412 | I6: 202.276 | J6: 206.255 | K6: 210.46 | L6: 213.734 | M6: 219.224 | N6: 224.89 | O6: 230.717 | P6: 236.688 | Q6: 242.787 | R6: 249 | S6: 255.314 | T6: 261.72 | U6: 268.21 | V6: 274.776 | W6: 281.411 | X6: 288.11 | Y6: 294.867 | Z6: 301.681 | AA6: 308.548 | AB6: 315.466 | AC6: 322.432 | AD6: 329.44 | AE6: 336.485 | AF6: 343.563 | AG6: 350.671 | AI6: CP, linha 64
A7: Tarifa teto de pista simples (com degraus) | B7: R$/km | D7: 0.0839635 | E7: 0.0948787 | F7: 0.107213 | G7: 0.122485 | H7: 0.122485 | I7: 0.122485 | J7: 0.122485 | K7: 0.122485 | L7: 0.122485 | M7: 0.122485 | N7: 0.122485 | O7: 0.122485 | P7: 0.122485 | Q7: 0.122485 | R7: 0.122485 | S7: 0.122485 | T7: 0.122485 | U7: 0.122485 | V7: 0.122485 | W7: 0.122485 | X7: 0.122485 | Y7: 0.122485 | Z7: 0.122485 | AA7: 0.122485 | AB7: 0.122485 | AC7: 0.122485 | AD7: 0.122485 | AE7: 0.122485 | AF7: 0.122485 | AG7: 0.122485 | AI7: CP, linha 81
A8: Extensão cobrada em pista simples | B8: km | D8: 459.344 | E8: 459.344 | F8: 459.344 | G8: 395.484 | H8: 349.984 | I8: 273.211 | J8: 253.731 | K8: 193.251 | L8: 152.761 | M8: 152.761 | N8: 152.761 | O8: 152.761 | P8: 152.761 | Q8: 152.761 | R8: 152.761 | S8: 152.761 | T8: 152.761 | U8: 152.761 | V8: 152.761 | W8: 152.761 | X8: 152.761 | Y8: 152.761 | Z8: 152.761 | AA8: 152.761 | AB8: 152.761 | AC8: 152.761 | AD8: 152.761 | AE8: 152.761 | AF8: 152.761 | AG8: 152.761 | AI8: CP, linha 112
A9: Extensão cobrada em pista dupla | B9: km | D9: 182.43 | E9: 182.43 | F9: 182.43 | G9: 246.29 | H9: 291.79 | I9: 368.563 | J9: 388.043 | K9: 448.523 | L9: 489.013 | M9: 489.013 | N9: 489.013 | O9: 489.013 | P9: 489.013 | Q9: 489.013 | R9: 489.013 | S9: 489.013 | T9: 489.013 | U9: 489.013 | V9: 489.013 | W9: 489.013 | X9: 489.013 | Y9: 489.013 | Z9: 489.013 | AA9: 489.013 | AB9: 489.013 | AC9: 489.013 | AD9: 489.013 | AE9: 489.013 | AF9: 489.013 | AG9: 489.013 | AI9: CP, linha 128
A10: Inadimplência do free flow | B10: % | D10: 0.12 | E10: 0.11 | F10: 0.1 | G10: 0.09 | H10: 0.08 | I10: 0.07 | J10: 0.06 | K10: 0.05 | L10: 0.04 | M10: 0.03 | N10: 0.03 | O10: 0.03 | P10: 0.03 | Q10: 0.03 | R10: 0.03 | S10: 0.03 | T10: 0.03 | U10: 0.03 | V10: 0.03 | W10: 0.03 | X10: 0.03 | Y10: 0.03 | Z10: 0.03 | AA10: 0.02 | AB10: 0.02 | AC10: 0.02 | AD10: 0.02 | AE10: 0.02 | AF10: 0.02 | AG10: 0.02 | AI10: CP, linha 79
A12: RECEITA (tarifa teto, sem desconto)
A13: Receita tarifária | B13: R$ mi | C13: =SUM(D13:AG13) -> 63807.803 | D13: 442.894 | E13: 914.099 | F13: 1093.86 | G13: 1319.93 | H13: 1409.88 | I13: 1511.84 | J13: 1595.8 | K13: 1681.21 | L13: 1843.56 | M13: 1910.48 | N13: 1960.09 | O13: 2011.1 | P13: 2063.39 | Q13: 2116.79 | R13: 2171.19 | S13: 2226.49 | T13: 2282.59 | U13: 2339.44 | V13: 2396.95 | W13: 2455.08 | X13: 2513.77 | Y13: 2572.99 | Z13: 2632.7 | AA13: 2720.27 | AB13: 2781.52 | AC13: 2843.21 | AD13: 2905.27 | AE13: 2967.68 | AF13: 3030.38 | AG13: 3093.35 | AI13: FS, linha 60
A14: Receita de recuperação (cobrança de inadimplentes) | B14: R$ mi | C14: =SUM(D14:AG14) -> 280.84494 | D14: 7.3072 | E14: 13.6635 | F14: 14.6938 | G14: 15.7786 | H14: 14.8176 | I14: 13.7535 | J14: 12.312 | K14: 10.6964 | L14: 9.28642 | M14: 7.14431 | N14: 7.3296 | O14: 7.52015 | P14: 7.71546 | Q14: 7.91498 | R14: 8.11822 | S14: 8.3248 | T14: 8.53442 | U14: 8.74681 | V14: 8.96171 | W14: 9.17889 | X14: 9.39818 | Y14: 9.61943 | Z14: 9.84254 | AA14: 6.71161 | AB14: 6.86266 | AC14: 7.01476 | AD14: 7.16781 | AE14: 7.32169 | AF14: 7.47631 | AG14: 7.63158 | AI14: FS, linha 61
A15: Juros e mora | B15: R$ mi | C15: =SUM(D15:AG15) -> 337.27949 | D15: 5.15948 | E15: 9.78252 | F15: 10.7259 | G15: 11.8488 | H15: 11.6159 | I15: 11.3854 | J15: 10.9714 | K15: 10.4885 | L15: 10.3402 | M15: 9.59805 | N15: 9.82274 | O15: 10.0561 | P15: 10.2968 | Q15: 10.5438 | R15: 10.7962 | S15: 11.0533 | T15: 11.3146 | U15: 11.5798 | V15: 11.8483 | W15: 12.1198 | X15: 12.3941 | Y15: 12.671 | Z15: 12.9502 | AA15: 11.7978 | AB15: 12.0492 | AC15: 12.3023 | AD15: 12.5569 | AE15: 12.8128 | AF15: 13.0698 | AG15: 13.3278 | AI15: FS, linha 62
A16: Compensação de evasão (paga pelo poder concedente) | B16: R$ mi | C16: =SUM(D16:AG16) -> 1897.6449 | D16: 50.6962 | E16: 92.2569 | F16: 99.2137 | G16: 106.538 | H16: 100.05 | I16: 92.8647 | J16: 83.1314 | K16: 72.223 | L16: 62.7027 | M16: 48.239 | N16: 49.4901 | O16: 50.7767 | P16: 52.0954 | Q16: 53.4426 | R16: 54.8149 | S16: 56.2097 | T16: 57.6251 | U16: 59.0591 | V16: 60.5102 | W16: 61.9766 | X16: 63.4573 | Y16: 64.9512 | Z16: 66.4576 | AA16: 45.3174 | AB16: 46.3373 | AC16: 47.3642 | AD16: 48.3976 | AE16: 49.4367 | AF16: 50.4806 | AG16: 51.529 | AI16: FS, linha 63
A17: Receita acessória | B17: R$ mi | C17: =SUM(D17:AG17) -> 957.11801 | D17: 6.64341 | E17: 13.7115 | F17: 16.408 | G17: 19.799 | H17: 21.1482 | I17: 22.6777 | J17: 23.9369 | K17: 25.2182 | L17: 27.6535 | M17: 28.6572 | N17: 29.4014 | O17: 30.1666 | P17: 30.9508 | Q17: 31.7519 | R17: 32.5679 | S17: 33.3973 | T17: 34.2389 | U17: 35.0916 | V17: 35.9543 | W17: 36.8262 | X17: 37.7066 | Y17: 38.5949 | Z17: 39.4906 | AA17: 40.804 | AB17: 41.7229 | AC17: 42.6481 | AD17: 43.5791 | AE17: 44.5152 | AF17: 45.4558 | AG17: 46.4003 | AI17: FS, linha 65
A18: Deduções (ISS, PIS/COFINS) | B18: R$ mi | C18: =SUM(D18:AG18) -> 5885.5293 | D18: 44.7206 | E18: 91.0317 | F18: 107.738 | G18: 128.601 | H18: 135.909 | I18: 144.213 | J18: 150.652 | K18: 157.098 | L18: 170.53 | M18: 177.391 | N18: 181.932 | O18: 186.601 | P18: 191.387 | Q18: 196.276 | R18: 198.827 | S18: 203.889 | T18: 209.025 | U18: 214.229 | V18: 219.494 | W18: 224.816 | X18: 230.189 | Y18: 235.61 | Z18: 241.076 | AA18: 246.639 | AB18: 252.191 | AC18: 257.783 | AD18: 263.409 | AE18: 269.066 | AF18: 274.749 | AG18: 280.457 | AI18: FS, linha 66
A20: OPEX
A21: Conservação | B21: R$ mi | C21: =SUM(D21:AG21) -> 3399.391 | D21: 72.304 | E21: 72.1752 | F21: 84.6366 | G21: 94.0932 | H21: 102.388 | I21: 108.074 | J21: 113.632 | K21: 119.656 | L21: 119.656 | M21: 119.656 | N21: 119.656 | O21: 119.656 | P21: 119.656 | Q21: 119.656 | R21: 119.656 | S21: 119.656 | T21: 119.656 | U21: 119.656 | V21: 119.656 | W21: 119.656 | X21: 119.656 | Y21: 119.656 | Z21: 119.656 | AA21: 119.656 | AB21: 119.656 | AC21: 119.656 | AD21: 119.656 | AE21: 119.656 | AF21: 119.656 | AG21: 119.656 | AI21: CP, linha 220
A22: Monitoração | B22: R$ mi | C22: =SUM(D22:AG22) -> 117.41195 | D22: 8.17206 | E22: 3.28137 | F22: 3.38556 | G22: 3.45398 | H22: 3.52632 | I22: 4.46332 | J22: 3.59102 | K22: 3.62272 | L22: 3.62272 | M22: 3.62272 | N22: 4.63393 | O22: 3.62272 | P22: 3.62272 | Q22: 3.62272 | R22: 3.62272 | S22: 4.63393 | T22: 3.62272 | U22: 3.62272 | V22: 3.62272 | W22: 3.62272 | X22: 4.65103 | Y22: 3.63981 | Z22: 3.63981 | AA22: 3.63981 | AB22: 3.63981 | AC22: 4.65103 | AD22: 3.63981 | AE22: 3.63981 | AF22: 3.63981 | AG22: 3.63981 | AI22: CP, linha 227
A23: Operação (mão de obra, veículos, sistemas) | B23: R$ mi | C23: =SUM(D23:AG23) -> 2441.0306 | D23: 79.3501 | E23: 86.1272 | F23: 88.1313 | G23: 87.3053 | H23: 87.3053 | I23: 87.3053 | J23: 87.3053 | K23: 87.3053 | L23: 78.9001 | M23: 78.9001 | N23: 78.9001 | O23: 78.9001 | P23: 78.9001 | Q23: 78.9001 | R23: 78.9001 | S23: 78.9001 | T23: 78.9001 | U23: 78.9001 | V23: 78.9001 | W23: 78.9001 | X23: 78.9001 | Y23: 78.9001 | Z23: 78.9001 | AA23: 78.9001 | AB23: 78.9001 | AC23: 78.9001 | AD23: 78.9001 | AE23: 78.9001 | AF23: 78.9001 | AG23: 93.9934 | AI23: CP, linha 232
A24: Energia | B24: R$ mi | C24: =SUM(D24:AG24) -> 537.37406 | D24: 6.70467 | E24: 7.66321 | F24: 11.94354 | G24: 13.67727 | H24: 15.53266 | I24: 16.11954 | J24: 17.36082 | K24: 19.49446 | L24: 19.49441 | M24: 19.49433 | N24: 19.49502 | O24: 19.4941 | P24: 19.49503 | Q24: 19.49451 | R24: 19.49448 | S24: 19.4941 | T24: 19.49487 | U24: 19.49433 | V24: 19.4943 | W24: 19.49497 | X24: 19.49438 | Y24: 19.49419 | Z24: 19.49417 | AA24: 19.49471 | AB24: 19.49423 | AC24: 19.49478 | AD24: 19.4943 | AE24: 19.49409 | AF24: 19.49433 | AG24: 19.49426 | AI24: CP, linha 240
A25: Despesas administrativas | B25: R$ mi | C25: =SUM(D25:AG25) -> 151.41708 | D25: 3.1316 | E25: 5.33039 | F25: 5.26739 | G25: 5.25484 | H25: 5.25484 | I25: 5.25484 | J25: 5.25484 | K25: 5.25484 | L25: 5.06425 | M25: 5.06425 | N25: 5.06425 | O25: 5.06425 | P25: 5.06425 | Q25: 5.06425 | R25: 5.06425 | S25: 5.06425 | T25: 5.06425 | U25: 5.06425 | V25: 5.06425 | W25: 5.06425 | X25: 5.06425 | Y25: 5.06425 | Z25: 5.06425 | AA25: 5.06425 | AB25: 5.06425 | AC25: 5.06425 | AD25: 5.06425 | AE25: 5.06425 | AF25: 5.06425 | AG25: 5.06425 | AI25: CP, linha 247
A26: Opex socioambiental | B26: R$ mi | C26: =SUM(D26:AG26) -> 56.59491 | D26: 1.85281 | E26: 1.85281 | F26: 1.85281 | G26: 1.85281 | H26: 2.18968 | I26: 1.85281 | J26: 1.85281 | K26: 1.85281 | L26: 1.85281 | M26: 1.85281 | N26: 1.85281 | O26: 1.85281 | P26: 1.85281 | Q26: 1.85281 | R26: 1.85281 | S26: 1.85281 | T26: 1.85281 | U26: 1.85281 | V26: 1.85281 | W26: 2.18968 | X26: 1.85281 | Y26: 1.85281 | Z26: 1.85281 | AA26: 1.85281 | AB26: 1.85281 | AC26: 1.85281 | AD26: 1.85281 | AE26: 1.85281 | AF26: 1.85281 | AG26: 2.18968 | AI26: CP, linha 251
A27: Recursos vinculados (1% da receita) | B27: R$ mi | C27: =SUM(D27:AG27) -> 647.64947 | D27: 4.49537 | E27: 9.2781 | F27: 11.1027 | G27: 13.3973 | H27: 14.3103 | I27: 15.3452 | J27: 16.1973 | K27: 17.0643 | L27: 18.7122 | M27: 19.3914 | N27: 19.8949 | O27: 20.4127 | P27: 20.9434 | Q27: 21.4854 | R27: 22.0376 | S27: 22.5988 | T27: 23.1683 | U27: 23.7453 | V27: 24.3291 | W27: 24.9191 | X27: 25.5148 | Y27: 26.1159 | Z27: 26.7219 | AA27: 27.6107 | AB27: 28.2325 | AC27: 28.8585 | AD27: 29.4885 | AE27: 30.122 | AF27: 30.7584 | AG27: 31.3975 | AI27: CP, linha 253
A28: Verbas obrigatórias (fiscalização, tecnologia, infra resiliente) | B28: R$ mi | C28: =SUM(D28:AG28) -> 1466.0459 | D28: 31.7752 | E28: 36.558 | F28: 38.3826 | G28: 40.6772 | H28: 41.5901 | I28: 42.6251 | J28: 43.4772 | K28: 44.3442 | L28: 45.9921 | M28: 46.6713 | N28: 47.1748 | O28: 47.6926 | P28: 48.2232 | Q28: 48.7653 | R28: 49.3175 | S28: 49.8787 | T28: 50.4482 | U28: 51.0252 | V28: 51.609 | W28: 52.199 | X28: 52.7947 | Y28: 53.3957 | Z28: 54.0018 | AA28: 54.8906 | AB28: 55.5123 | AC28: 56.1384 | AD28: 56.7684 | AE28: 57.4018 | AF28: 58.0383 | AG28: 58.6774 | AI28: CP, linha 256
A29: Seguros e garantias | B29: R$ mi | C29: =SUM(D29:AG29) -> 258.24403 | D29: 5.82219 | E29: 6.84172 | F29: 11.3835 | G29: 10.8781 | H29: 10.7618 | I29: 9.92589 | J29: 9.72571 | K29: 9.72837 | L29: 7.19741 | M29: 7.23009 | N29: 7.24819 | O29: 7.31472 | P29: 7.50949 | Q29: 7.55991 | R29: 7.68354 | S29: 7.81831 | T29: 8.10075 | U29: 8.10929 | V29: 8.13272 | W29: 8.28618 | X29: 8.36593 | Y29: 8.42124 | Z29: 8.67116 | AA29: 8.76102 | AB29: 8.952 | AC29: 8.97313 | AD29: 9.08383 | AE29: 9.15214 | AF29: 10.276 | AG29: 10.3297 | AI29: CP, linha 261
A30: Opex total | B30: R$ mi | C30: =SUM(D30:AG30) -> 9075.159 | D30: 213.608 | E30: 229.108 | F30: 256.086 | G30: 270.59 | H30: 282.859 | I30: 290.966 | J30: 298.397 | K30: 308.323 | L30: 300.492 | M30: 301.883 | N30: 303.92 | O30: 304.01 | P30: 305.267 | Q30: 306.401 | R30: 307.629 | S30: 309.897 | T30: 310.308 | U30: 311.47 | V30: 312.661 | W30: 314.332 | X30: 316.294 | Y30: 316.54 | Z30: 318.002 | AA30: 319.87 | AB30: 321.304 | AC30: 323.589 | AD30: 323.948 | AE30: 325.283 | AF30: 327.68 | AG30: 344.442 | AI30: FS, linha 68
A32: CAPEX
A33: Trabalhos iniciais, restauração e manutenção | B33: R$ mi | C33: =SUM(D33:AG33) -> 6389.9641 | D33: 312.224 | E33: 308.055 | F33: 512.11 | G33: 544.373 | H33: 476.676 | I33: 512.527 | J33: 368.653 | K33: 277.79 | L33: 266.344 | M33: 97.9888 | N33: 87.7377 | O33: 50.4343 | P33: 123.117 | Q33: 108.773 | R33: 80.9662 | S33: 123.423 | T33: 260.631 | U33: 192.605 | V33: 136.874 | W33: 154.145 | X33: 117.083 | Y33: 44.4039 | Z33: 186.516 | AA33: 105.142 | AB33: 219.616 | AC33: 161.017 | AD33: 197.139 | AE33: 171.861 | AF33: 91.2422 | AG33: 100.497 | AI33: CP, linha 277
A34: Ampliação de capacidade (duplicações, faixas, OAEs) | B34: R$ mi | C34: =SUM(D34:AG34) -> 6360.013 | D34: 21.782 | E34: 22.0099 | F34: 1537.72 | G34: 1275.13 | H34: 1168.81 | I34: 748.618 | J34: 722.301 | K34: 674.909 | L34: 19.1544 | M34: 25.1884 | N34: 3.97476 | O34: 2.83434 | P34: 5.57768 | Q34: 3.65073 | R34: 13.0773 | S34: 4.72778 | T34: 10.2778 | U34: 7.28665 | V34: 4.58565 | W34: 14.8342 | X34: 4.99137 | Y34: 3.13717 | Z34: 7.47696 | AA34: 5.23135 | AB34: 17.0484 | AC34: 5.6867 | AD34: 6.48244 | AE34: 6.62412 | AF34: 3.72704 | AG34: 13.1579 | AI34: CP, linha 281
A35: Edificações | B35: R$ mi | C35: =SUM(D35:AG35) -> 191.9123 | D35: 22.2909 | E35: 98.5188 | F35: 71.1026 | G35: 0 | H35: 0 | I35: 0 | J35: 0 | K35: 0 | L35: 0 | M35: 0 | N35: 0 | O35: 0 | P35: 0 | Q35: 0 | R35: 0 | S35: 0 | T35: 0 | U35: 0 | V35: 0 | W35: 0 | X35: 0 | Y35: 0 | Z35: 0 | AA35: 0 | AB35: 0 | AC35: 0 | AD35: 0 | AE35: 0 | AF35: 0 | AG35: 0 | AI35: CP, linha 294
A36: Equipamentos e sistemas (pórticos, veículos) | B36: R$ mi | C36: =SUM(D36:AG36) -> 923.26932 | D36: 96.1465 | E36: 36.0921 | F36: 172.411 | G36: 2.66079 | H36: 5.81927 | I36: 16.1112 | J36: 4.14776 | K36: 45.0909 | L36: 4.31966 | M36: 52.7205 | N36: 31.0463 | O36: 31.9818 | P36: 42.7252 | Q36: 2.6043 | R36: 18.9012 | S36: 20.3977 | T36: 53.597 | U36: 31.4752 | V36: 4.08819 | W36: 3.20371 | X36: 31.2778 | Y36: 46.1954 | Z36: 42.4937 | AA36: 51.5232 | AB36: 5.21802 | AC36: 13.9599 | AD36: 4.14776 | AE36: 31.1763 | AF36: 18.2343 | AG36: 3.50266 | AI36: CP, linha 304
A37: Passivos ambientais | B37: R$ mi | C37: =SUM(D37:AG37) -> 21.7815 | D37: 4.3563 | E37: 4.3563 | F37: 4.3563 | G37: 4.3563 | H37: 4.3563 | I37: 0 | J37: 0 | K37: 0 | L37: 0 | M37: 0 | N37: 0 | O37: 0 | P37: 0 | Q37: 0 | R37: 0 | S37: 0 | T37: 0 | U37: 0 | V37: 0 | W37: 0 | X37: 0 | Y37: 0 | Z37: 0 | AA37: 0 | AB37: 0 | AC37: 0 | AD37: 0 | AE37: 0 | AF37: 0 | AG37: 0 | AI37: CP, linha 319
A38: Desapropriação | B38: R$ mi | C38: =SUM(D38:AG38) -> 445.82631 | D38: 0 | E38: 0 | F38: 119.292 | G38: 46.5931 | H38: 124.246 | I38: 124.479 | J38: 3.96071 | K38: 27.2555 | L38: 0 | M38: 0 | N38: 0 | O38: 0 | P38: 0 | Q38: 0 | R38: 0 | S38: 0 | T38: 0 | U38: 0 | V38: 0 | W38: 0 | X38: 0 | Y38: 0 | Z38: 0 | AA38: 0 | AB38: 0 | AC38: 0 | AD38: 0 | AE38: 0 | AF38: 0 | AG38: 0 | AI38: CP, linha 321
A39: Ressarcimento dos estudos e da B3 | B39: R$ mi | C39: =SUM(D39:AG39) -> 6.20227 | D39: 6.20227 | E39: 0 | F39: 0 | G39: 0 | H39: 0 | I39: 0 | J39: 0 | K39: 0 | L39: 0 | M39: 0 | N39: 0 | O39: 0 | P39: 0 | Q39: 0 | R39: 0 | S39: 0 | T39: 0 | U39: 0 | V39: 0 | W39: 0 | X39: 0 | Y39: 0 | Z39: 0 | AA39: 0 | AB39: 0 | AC39: 0 | AD39: 0 | AE39: 0 | AF39: 0 | AG39: 0 | AI39: CP, linha 271
A40: Capex total | B40: R$ mi | C40: =SUM(D40:AG40) -> 14338.963 | D40: 463.002 | E40: 469.032 | F40: 2416.99 | G40: 1873.11 | H40: 1779.9 | I40: 1401.74 | J40: 1099.06 | K40: 1025.05 | L40: 289.818 | M40: 175.898 | N40: 122.759 | O40: 85.2505 | P40: 171.42 | Q40: 115.028 | R40: 112.945 | S40: 148.548 | T40: 324.506 | U40: 231.367 | V40: 145.548 | W40: 172.183 | X40: 153.352 | Y40: 93.7365 | Z40: 236.487 | AA40: 161.896 | AB40: 241.882 | AC40: 180.663 | AD40: 207.769 | AE40: 209.662 | AF40: 113.204 | AG40: 117.157 | AI40: FS, linha 79
A42: OUTROS (para conferência)
A43: Variação do capital de giro | B43: R$ mi | C43: =SUM(D43:AG43) -> -0.0003 | D43: 37.8109 | E43: 46.762 | F43: 16.1608 | G43: 21.3976 | H43: 7.5956 | I43: 8.85694 | J43: 6.93437 | K43: 6.83044 | L43: 14.8345 | M43: 7.41889 | N43: 4.93943 | O43: 5.14432 | P43: 5.22715 | Q43: 5.42381 | R43: 2.92501 | S43: 5.58736 | T43: 5.80269 | U43: 6.06969 | V43: 6.11173 | W43: 6.11963 | X43: 6.26683 | Y43: 6.4314 | Z43: 6.40939 | AA43: 6.87122 | AB43: 6.87722 | AC43: 7.32756 | AD43: 7.49523 | AE43: 8.03917 | AF43: 8.84182 | AG43: -292.513 | AI43: FS, linha 70
A44: Amortização do intangível | B44: R$ mi | C44: =SUM(D44:AG44) -> 14338.948 | D44: 0 | E44: 4.0048 | F44: 9.92958 | G44: 44.5511 | H44: 76.4519 | I44: 113.312 | J44: 147.906 | K44: 181.5 | L44: 227.279 | M44: 252.014 | N44: 272.33 | O44: 292.765 | P44: 313.572 | Q44: 338.992 | R44: 359.803 | S44: 386.748 | T44: 417.473 | U44: 460.133 | V44: 501.752 | W44: 541.697 | X44: 587.22 | Y44: 635.534 | Z44: 682.581 | AA44: 750.973 | AB44: 818.116 | AC44: 908.671 | AD44: 1002.48 | AE44: 1125.32 | AF44: 1291.26 | AG44: 1594.58 | AI44: FS, linha 15
...

Sheet 3. Receita
A1: 3. Receita
A2: Receita com o desconto do lance: receita do MEF × (1 − desconto) × fator de tráfego. A receita acessória não depende da tarifa.
A4: Ano da concessão | B4: Unidade | C4: Total | D4: 1 | E4: 2 | F4: 3 | G4: 4 | H4: 5 | I4: 6 | J4: 7 | K4: 8 | L4: 9 | M4: 10 | N4: 11 | O4: 12 | P4: 13 | Q4: 14 | R4: 15 | S4: 16 | T4: 17 | U4: 18 | V4: 19 | W4: 20 | X4: 21 | Y4: 22 | Z4: 23 | AA4: 24 | AB4: 25 | AC4: 26 | AD4: 27 | AE4: 28 | AF4: 29 | AG4: 30
A5: TRÁFEGO E TARIFA (para entender a receita)
A6: Veículos equivalentes | B6: milhões/ano | D6: =Dados_MEF!D6 -> 111.192 | E6: =Dados_MEF!E6 -> 192.654 | F6: =Dados_MEF!F6 -> 194.02 | G6: =Dados_MEF!G6 -> 194.826 | H6: =Dados_MEF!H6 -> 198.412 | I6: =Dados_MEF!I6 -> 202.276 | J6: =Dados_MEF!J6 -> 206.255 | K6: =Dados_MEF!K6 -> 210.46 | ... AG6: =Dados_MEF!AG6 -> 350.671
A7: Tarifa média por veículo equivalente (MEF) | B7: R$ | D7: =Dados_MEF!D13/Dados_MEF!D6 -> 3.9831463 | E7: =Dados_MEF!E13/Dados_MEF!E6 -> 4.7447704 | F7: =Dados_MEF!F13/Dados_MEF!F6 -> 5.6378724 | G7: =Dados_MEF!G13/Dados_MEF!G6 -> 6.7749171 | H7: =Dados_MEF!H13/Dados_MEF!H6 -> 7.1058202 | I7: =Dados_MEF!I13/Dados_MEF!I6 -> 7.4741442 | J7: =Dados_MEF!J13/Dados_MEF!J6 -> 7.7370246 | K7: =Dados_MEF!K13/Dados_MEF!K6 -> 7.9882638 | ... AG7: =Dados_MEF!AG13/Dados_MEF!AG6 -> 8.8212313
A8: Fator de receita: (1 − desconto) × fator de tráfego | B8: x | D8: =(1-'1. Premissas'!$B$6)*'2. Cenários'!$E$5 -> 0.74713112 | E8: =(1-'1. Premissas'!$B$6)*'2. Cenários'!$E$5 -> 0.74713112 | F8: =(1-'1. Premissas'!$B$6)*'2. Cenários'!$E$5 -> 0.74713112 | G8: =(1-'1. Premissas'!$B$6)*'2. Cenários'!$E$5 -> 0.74713112 | H8: =(1-'1. Premissas'!$B$6)*'2. Cenários'!$E$5 -> 0.74713112 | I8: =(1-'1. Premissas'!$B$6)*'2. Cenários'!$E$5 -> 0.74713112 | J8: =(1-'1. Premissas'!$B$6)*'2. Cenários'!$E$5 -> 0.74713112 | K8: =(1-'1. Premissas'!$B$6)*'2. Cenários'!$E$5 -> 0.74713112 | ... AG8: =(1-'1. Premissas'!$B$6)*'2. Cenários'!$E$5 -> 0.74713112
A9: RECEITA
A10: Receita tarifária | B10: R$ mi | D10: =Dados_MEF!D13*D$8 -> 330.89989 | E10: =Dados_MEF!E13*E$8 -> 682.95181 | F10: =Dados_MEF!F13*F$8 -> 817.25685 | G10: =Dados_MEF!G13*G$8 -> 986.16078 | H10: =Dados_MEF!H13*H$8 -> 1053.3652 | I10: =Dados_MEF!I13*I$8 -> 1129.5427 | J10: =Dados_MEF!J13*J$8 -> 1192.2718 | K10: =Dados_MEF!K13*K$8 -> 1256.0843 | ... AG10: =Dados_MEF!AG13*AG$8 -> 2311.1381
A11: Receita de recuperação + juros e mora | B11: R$ mi | D11: =(Dados_MEF!D14+Dados_MEF!D15)*D$8 -> 9.3142446 | E11: =(Dados_MEF!E14+Dados_MEF!E15)*E$8 -> 17.517251 | F11: =(Dados_MEF!F14+Dados_MEF!F15)*F$8 -> 18.991849 | G11: =(Dados_MEF!G14+Dados_MEF!G15)*G$8 -> 20.64129 | H11: =(Dados_MEF!H14+Dados_MEF!H15)*H$8 -> 19.749291 | I11: =(Dados_MEF!I14+Dados_MEF!I15)*I$8 -> 18.782055 | J11: =(Dados_MEF!J14+Dados_MEF!J15)*J$8 -> 17.395753 | K11: =(Dados_MEF!K14+Dados_MEF!K15)*K$8 -> 15.827898 | ... AG11: =(Dados_MEF!AG14+Dados_MEF!AG15)*AG$8 -> 15.659405
A12: Compensação de evasão | B12: R$ mi | D12: =Dados_MEF!D16*D$8 -> 37.876709 | E12: =Dados_MEF!E16*E$8 -> 68.928001 | F12: =Dados_MEF!F16*F$8 -> 74.125643 | G12: =Dados_MEF!G16*G$8 -> 79.597855 | H12: =Dados_MEF!H16*H$8 -> 74.750469 | I12: =Dados_MEF!I16*I$8 -> 69.382107 | J12: =Dados_MEF!J16*J$8 -> 62.110056 | K12: =Dados_MEF!K16*K$8 -> 53.960051 | ... AG12: =Dados_MEF!AG16*AG$8 -> 38.49892
A13: Receita acessória | B13: R$ mi | D13: =Dados_MEF!D17 -> 6.64341 | E13: =Dados_MEF!E17 -> 13.7115 | F13: =Dados_MEF!F17 -> 16.408 | G13: =Dados_MEF!G17 -> 19.799 | H13: =Dados_MEF!H17 -> 21.1482 | I13: =Dados_MEF!I17 -> 22.6777 | J13: =Dados_MEF!J17 -> 23.9369 | K13: =Dados_MEF!K17 -> 25.2182 | ... AG13: =Dados_MEF!AG17 -> 46.4003
A14: Receita bruta | B14: R$ mi | D14: =SUM(D10:D13) -> 384.73425 | E14: =SUM(E10:E13) -> 783.10856 | F14: =SUM(F10:F13) -> 926.78234 | G14: =SUM(G10:G13) -> 1106.1989 | H14: =SUM(H10:H13) -> 1169.0132 | I14: =SUM(I10:I13) -> 1240.3846 | J14: =SUM(J10:J13) -> 1295.7146 | K14: =SUM(K10:K13) -> 1351.0905 | ... AG14: =SUM(AG10:AG13) -> 2411.6967
A15: (−) Deduções | B15: R$ mi | D15: =-D14*'1. Premissas'!$B$12 -> -33.664247 | E15: =-E14*'1. Premissas'!$B$12 -> -68.521999 | F15: =-F14*'1. Premissas'!$B$12 -> -81.093455 | G15: =-G14*'1. Premissas'!$B$12 -> -96.792406 | H15: =-H14*'1. Premissas'!$B$12 -> -102.28865 | I15: =-I14*'1. Premissas'!$B$12 -> -108.53365 | J15: =-J14*'1. Premissas'!$B$12 -> -113.37502 | K15: =-K14*'1. Premissas'!$B$12 -> -118.22042 | ... AG15: =-AG14*'1. Premissas'!$B$12 -> -211.02346
A16: Receita líquida | B16: R$ mi | D16: =D14+D15 -> 351.07001 | E16: =E14+E15 -> 714.58656 | F16: =F14+F15 -> 845.68889 | G16: =G14+G15 -> 1009.4065 | H16: =H14+H15 -> 1066.7245 | I16: =I14+I15 -> 1131.8509 | J16: =J14+J15 -> 1182.3395 | K16: =K14+K15 -> 1232.87 | ... AG16: =AG14+AG15 -> 2200.6732

Sheet 4. Custos
A1: 4. Custos
A2: Opex e capex do MEF ajustados pelo cenário. As verbas vinculadas acompanham a receita (com desconto, caem junto).
A4: Ano da concessão | B4: Unidade | C4: Total | D4: 1 | E4: 2 | F4: 3 | G4: 4 | H4: 5 | I4: 6 | J4: 7 | K4: 8 | L4: 9 | M4: 10 | N4: 11 | O4: 12 | P4: 13 | Q4: 14 | R4: 15 | S4: 16 | T4: 17 | U4: 18 | V4: 19 | W4: 20 | X4: 21 | Y4: 22 | Z4: 23 | AA4: 24 | AB4: 25 | AC4: 26 | AD4: 27 | AE4: 28 | AF4: 29 | AG4: 30
A5: OPEX
A6: Opex fixo (opex do MEF sem as verbas vinculadas) | B6: R$ mi | D6: =(Dados_MEF!D30-2*Dados_MEF!D27)*'2. Cenários'!$E$7 -> 204.61726 | E6: =(Dados_MEF!E30-2*Dados_MEF!E27)*'2. Cenários'!$E$7 -> 210.5518 | F6: =(Dados_MEF!F30-2*Dados_MEF!F27)*'2. Cenários'!$E$7 -> 233.8806 | G6: =(Dados_MEF!G30-2*Dados_MEF!G27)*'2. Cenários'!$E$7 -> 243.7954 | H6: =(Dados_MEF!H30-2*Dados_MEF!H27)*'2. Cenários'!$E$7 -> 254.2384 | I6: =(Dados_MEF!I30-2*Dados_MEF!I27)*'2. Cenários'!$E$7 -> 260.2756 | J6: =(Dados_MEF!J30-2*Dados_MEF!J27)*'2. Cenários'!$E$7 -> 266.0024 | K6: =(Dados_MEF!K30-2*Dados_MEF!K27)*'2. Cenários'!$E$7 -> 274.1944 | ... AG6: =(Dados_MEF!AG30-2*Dados_MEF!AG27)*'2. Cenários'!$E$7 -> 281.647
A7: Verbas vinculadas (2% da receita bruta) | B7: R$ mi | D7: =('3. Receita'!D10+'3. Receita'!D13)*'1. Premissas'!$B$14 -> 6.750866 | E7: =('3. Receita'!E10+'3. Receita'!E13)*'1. Premissas'!$B$14 -> 13.933266 | F7: =('3. Receita'!F10+'3. Receita'!F13)*'1. Premissas'!$B$14 -> 16.673297 | G7: =('3. Receita'!G10+'3. Receita'!G13)*'1. Premissas'!$B$14 -> 20.119196 | H7: =('3. Receita'!H10+'3. Receita'!H13)*'1. Premissas'!$B$14 -> 21.490269 | I7: =('3. Receita'!I10+'3. Receita'!I13)*'1. Premissas'!$B$14 -> 23.044408 | J7: =('3. Receita'!J10+'3. Receita'!J13)*'1. Premissas'!$B$14 -> 24.324175 | K7: =('3. Receita'!K10+'3. Receita'!K13)*'1. Premissas'!$B$14 -> 25.62605 | ... AG7: =('3. Receita'!AG10+'3. Receita'!AG13)*'1. Premissas'!$B$14 -> 47.150767
A8: Opex total | B8: R$ mi | D8: =D6+D7 -> 211.36813 | E8: =E6+E7 -> 224.48507 | F8: =F6+F7 -> 250.5539 | G8: =G6+G7 -> 263.9146 | H8: =H6+H7 -> 275.72867 | I8: =I6+I7 -> 283.32001 | J8: =J6+J7 -> 290.32657 | K8: =K6+K7 -> 299.82045 | ... AG8: =AG6+AG7 -> 328.79777
A9: CAPEX
A10: Capex total | B10: R$ mi | D10: =Dados_MEF!D40*'2. Cenários'!$E$6 -> 463.002 | E10: =Dados_MEF!E40*'2. Cenários'!$E$6 -> 469.032 | F10: =Dados_MEF!F40*'2. Cenários'!$E$6 -> 2416.99 | G10: =Dados_MEF!G40*'2. Cenários'!$E$6 -> 1873.11 | H10: =Dados_MEF!H40*'2. Cenários'!$E$6 -> 1779.9 | I10: =Dados_MEF!I40*'2. Cenários'!$E$6 -> 1401.74 | J10: =Dados_MEF!J40*'2. Cenários'!$E$6 -> 1099.06 | K10: =Dados_MEF!K40*'2. Cenários'!$E$6 -> 1025.05 | ... AG10: =Dados_MEF!AG40*'2. Cenários'!$E$6 -> 117.157
A11: Amortização do intangível | B11: R$ mi | D11: =Dados_MEF!D44*'2. Cenários'!$E$6 -> 0 | E11: =Dados_MEF!E44*'2. Cenários'!$E$6 -> 4.0048 | F11: =Dados_MEF!F44*'2. Cenários'!$E$6 -> 9.92958 | G11: =Dados_MEF!G44*'2. Cenários'!$E$6 -> 44.5511 | H11: =Dados_MEF!H44*'2. Cenários'!$E$6 -> 76.4519 | I11: =Dados_MEF!I44*'2. Cenários'!$E$6 -> 113.312 | J11: =Dados_MEF!J44*'2. Cenários'!$E$6 -> 147.906 | K11: =Dados_MEF!K44*'2. Cenários'!$E$6 -> 181.5 | ... AG11: =Dados_MEF!AG44*'2. Cenários'!$E$6 -> 1594.58

Sheet 5. Caixa
A1: 5. Caixa
A2: Do EBITDA ao caixa disponível para a dívida (CFADS) e ao fluxo do projeto sem dívida.
A4: Ano da concessão | B4: Unidade | C4: Total | D4: 1 | E4: 2 | F4: 3 | G4: 4 | H4: 5 | I4: 6 | J4: 7 | K4: 8 | L4: 9 | M4: 10 | N4: 11 | O4: 12 | P4: 13 | Q4: 14 | R4: 15 | S4: 16 | T4: 17 | U4: 18 | V4: 19 | W4: 20 | X4: 21 | Y4: 22 | Z4: 23 | AA4: 24 | AB4: 25 | AC4: 26 | AD4: 27 | AE4: 28 | AF4: 29 | AG4: 30
A5: RESULTADO
A6: Receita líquida | B6: R$ mi | D6: ='3. Receita'!D16 -> 351.07001 | E6: ='3. Receita'!E16 -> 714.58656 | F6: ='3. Receita'!F16 -> 845.68889 | G6: ='3. Receita'!G16 -> 1009.4065 | H6: ='3. Receita'!H16 -> 1066.7245 | I6: ='3. Receita'!I16 -> 1131.8509 | J6: ='3. Receita'!J16 -> 1182.3395 | K6: ='3. Receita'!K16 -> 1232.87 | ... AG6: ='3. Receita'!AG16 -> 2200.6732
A7: (−) Opex | B7: R$ mi | D7: =-'4. Custos'!D8 -> -211.36813 | E7: =-'4. Custos'!E8 -> -224.48507 | F7: =-'4. Custos'!F8 -> -250.5539 | G7: =-'4. Custos'!G8 -> -263.9146 | H7: =-'4. Custos'!H8 -> -275.72867 | I7: =-'4. Custos'!I8 -> -283.32001 | J7: =-'4. Custos'!J8 -> -290.32657 | K7: =-'4. Custos'!K8 -> -299.82045 | ... AG7: =-'4. Custos'!AG8 -> -328.79777
A8: EBITDA | B8: R$ mi | D8: =D6+D7 -> 139.70188 | E8: =E6+E7 -> 490.1015 | F8: =F6+F7 -> 595.13499 | G8: =G6+G7 -> 745.49193 | H8: =H6+H7 -> 790.99586 | I8: =I6+I7 -> 848.53092 | J8: =J6+J7 -> 892.01295 | K8: =K6+K7 -> 933.0496 | ... AG8: =AG6+AG7 -> 1871.8755
A9: Margem EBITDA | B9: % | D9: =D8/D6 -> 0.39793169 | E9: =E8/E6 -> 0.68585322 | F9: =F8/F6 -> 0.70372805 | G9: =G8/G6 -> 0.73854479 | H9: =H8/H6 -> 0.7415184 | I9: =I8/I6 -> 0.74968434 | J9: =J8/J6 -> 0.75444738 | K9: =K8/K6 -> 0.75681099 | ... AG9: =AG8/AG6 -> 0.85059219
A10: (−) Amortização | B10: R$ mi | D10: =-'4. Custos'!D11 -> 0 | E10: =-'4. Custos'!E11 -> -4.0048 | F10: =-'4. Custos'!F11 -> -9.92958 | G10: =-'4. Custos'!G11 -> -44.5511 | H10: =-'4. Custos'!H11 -> -76.4519 | I10: =-'4. Custos'!I11 -> -113.312 | J10: =-'4. Custos'!J11 -> -147.906 | K10: =-'4. Custos'!K11 -> -181.5 | ... AG10: =-'4. Custos'!AG11 -> -1594.58
A11: EBIT | B11: R$ mi | D11: =D8+D10 -> 139.70188 | E11: =E8+E10 -> 486.0967 | F11: =F8+F10 -> 585.20541 | G11: =G8+G10 -> 700.94083 | H11: =H8+H10 -> 714.54396 | I11: =I8+I10 -> 735.21892 | J11: =J8+J10 -> 744.10695 | K11: =K8+K10 -> 751.5496 | ... AG11: =AG8+AG10 -> 277.29545
A12: (−) IR/CSLL | B12: R$ mi | D12: =-MAX(0,D11)*'1. Premissas'!$B$13 -> -47.49864 | E12: =-MAX(0,E11)*'1. Premissas'!$B$13 -> -165.27288 | F12: =-MAX(0,F11)*'1. Premissas'!$B$13 -> -198.96984 | G12: =-MAX(0,G11)*'1. Premissas'!$B$13 -> -238.31988 | H12: =-MAX(0,H11)*'1. Premissas'!$B$13 -> -242.94495 | I12: =-MAX(0,I11)*'1. Premissas'!$B$13 -> -249.97443 | J12: =-MAX(0,J11)*'1. Premissas'!$B$13 -> -252.99636 | K12: =-MAX(0,K11)*'1. Premissas'!$B$13 -> -255.52686 | ... AG12: =-MAX(0,AG11)*'1. Premissas'!$B$13 -> -94.280454
A13: CAIXA
A14: (−) Variação do capital de giro | B14: R$ mi | D14: =-Dados_MEF!D43*'3. Receita'!D$8 -> -28.2497 | E14: =-Dados_MEF!E43*'3. Receita'!E$8 -> -34.937346 | F14: =-Dados_MEF!F43*'3. Receita'!F$8 -> -12.074237 | G14: =-Dados_MEF!G43*'3. Receita'!G$8 -> -15.986813 | H14: =-Dados_MEF!H43*'3. Receita'!H$8 -> -5.6749091 | I14: =-Dados_MEF!I43*'3. Receita'!I$8 -> -6.6172955 | J14: =-Dados_MEF!J43*'3. Receita'!J$8 -> -5.1808836 | K14: =-Dados_MEF!K43*'3. Receita'!K$8 -> -5.1032343 | ... AG14: =-Dados_MEF!AG43*'3. Receita'!AG$8 -> 218.54557
A15: Caixa operacional (CFADS) | B15: R$ mi | D15: =D8+D12+D14 -> 63.953541 | E15: =E8+E12+E14 -> 289.89128 | F15: =F8+F12+F14 -> 384.09091 | G15: =G8+G12+G14 -> 491.18523 | H15: =H8+H12+H14 -> 542.37601 | I15: =I8+I12+I14 -> 591.93919 | J15: =J8+J12+J14 -> 633.83571 | K15: =K8+K12+K14 -> 672.4195 | ... AG15: =AG8+AG12+AG14 -> 1996.1406
A16: (−) Capex | B16: R$ mi | D16: =-'4. Custos'!D10 -> -463.002 | E16: =-'4. Custos'!E10 -> -469.032 | F16: =-'4. Custos'!F10 -> -2416.99 | G16: =-'4. Custos'!G10 -> -1873.11 | H16: =-'4. Custos'!H10 -> -1779.9 | I16: =-'4. Custos'!I10 -> -1401.74 | J16: =-'4. Custos'!J10 -> -1099.06 | K16: =-'4. Custos'!K10 -> -1025.05 | ... AG16: =-'4. Custos'!AG10 -> -117.157
A17: Fluxo de caixa do projeto (sem dívida) | B17: R$ mi | C17: =IRR(D17:AG17) -> 0.077117609 | D17: =D15+D16 -> -399.04846 | E17: =E15+E16 -> -179.14072 | F17: =F15+F16 -> -2032.8991 | G17: =G15+G16 -> -1381.9248 | H17: =H15+H16 -> -1237.524 | I17: =I15+I16 -> -809.80081 | J17: =J15+J16 -> -465.22429 | K17: =K15+K16 -> -352.6305 | ... AG17: =AG15+AG16 -> 1878.9836

Sheet 6. Dívida
A1: 6. Dívida
A2: Tamanho da dívida pelo ICSD: parcela máxima = CFADS ÷ ICSD; dívida = valor presente das parcelas.
A4: Ano da concessão | B4: Unidade | C4: Total | D4: 1 | E4: 2 | F4: 3 | G4: 4 | H4: 5 | I4: 6 | J4: 7 | K4: 8 | L4: 9 | M4: 10 | N4: 11 | O4: 12 | P4: 13 | Q4: 14 | R4: 15 | S4: 16 | T4: 17 | U4: 18 | V4: 19 | W4: 20 | X4: 21 | Y4: 22 | Z4: 23 | AA4: 24 | AB4: 25 | AC4: 26 | AD4: 27 | AE4: 28 | AF4: 29 | AG4: 30
A5: DIMENSIONAMENTO
A6: Ano de amortização? (1 = sim) | B6: flag | D6: =IF(AND(D$4>='1. Premissas'!$B$18,D$4<='1. Premissas'!$B$19),1,0) -> 0 | E6: =IF(AND(E$4>='1. Premissas'!$B$18,E$4<='1. Premissas'!$B$19),1,0) -> 0 | F6: =IF(AND(F$4>='1. Premissas'!$B$18,F$4<='1. Premissas'!$B$19),1,0) -> 0 | G6: =IF(AND(G$4>='1. Premissas'!$B$18,G$4<='1. Premissas'!$B$19),1,0) -> 0 | H6: =IF(AND(H$4>='1. Premissas'!$B$18,H$4<='1. Premissas'!$B$19),1,0) -> 0 | I6: =IF(AND(I$4>='1. Premissas'!$B$18,I$4<='1. Premissas'!$B$19),1,0) -> 0 | J6: =IF(AND(J$4>='1. Premissas'!$B$18,J$4<='1. Premissas'!$B$19),1,0) -> 0 | K6: =IF(AND(K$4>='1. Premissas'!$B$18,K$4<='1. Premissas'!$B$19),1,0) -> 0 | ... AG6: =IF(AND(AG$4>='1. Premissas'!$B$18,AG$4<='1. Premissas'!$B$19),1,0) -> 0
A7: Serviço máximo da dívida (CFADS ÷ ICSD) | B7: R$ mi | D7: ='5. Caixa'!D15/'1. Premissas'!$B$17*D6 -> 0 | E7: ='5. Caixa'!E15/'1. Premissas'!$B$17*E6 -> 0 | F7: ='5. Caixa'!F15/'1. Premissas'!$B$17*F6 -> 0 | G7: ='5. Caixa'!G15/'1. Premissas'!$B$17*G6 -> 0 | H7: ='5. Caixa'!H15/'1. Premissas'!$B$17*H6 -> 0 | I7: ='5. Caixa'!I15/'1. Premissas'!$B$17*I6 -> 0 | J7: ='5. Caixa'!J15/'1. Premissas'!$B$17*J6 -> 0 | K7: ='5. Caixa'!K15/'1. Premissas'!$B$17*K6 -> 0 | ... AG7: ='5. Caixa'!AG15/'1. Premissas'!$B$17*AG6 -> 0
A8: CRONOGRAMA
A9: Saldo inicial | B9: R$ mi | D9: =0 -> 0 | E9: =D12 -> 292.16873 | F9: =E12 -> 588.14258 | G9: =F12 -> 2113.3388 | H9: =G12 -> 3295.3298 | I9: =H12 -> 4418.5023 | J9: =I12 -> 5303.044 | K9: =J12 -> 5996.5852 | L9: =K12 -> 6643.4238 | ... AG9: =AF12 -> 0
A10: (+) Captação | B10: R$ mi | D10: =IF(D$4<'1. Premissas'!$B$18,$C$20*'4. Custos'!D10,0) -> 292.16873 | E10: =IF(E$4<'1. Premissas'!$B$18,$C$20*'4. Custos'!E10,0) -> 295.97385 | F10: =IF(F$4<'1. Premissas'!$B$18,$C$20*'4. Custos'!F10,0) -> 1525.1962 | G10: =IF(G$4<'1. Premissas'!$B$18,$C$20*'4. Custos'!G10,0) -> 1181.9909 | H10: =IF(H$4<'1. Premissas'!$B$18,$C$20*'4. Custos'!H10,0) -> 1123.1725 | I10: =IF(I$4<'1. Premissas'!$B$18,$C$20*'4. Custos'!I10,0) -> 884.54175 | J10: =IF(J$4<'1. Premissas'!$B$18,$C$20*'4. Custos'!J10,0) -> 693.54121 | K10: =IF(K$4<'1. Premissas'!$B$18,$C$20*'4. Custos'!K10,0) -> 646.83858 | ... AG10: =IF(AG$4<'1. Premissas'!$B$18,$C$20*'4. Custos'!AG10,0) -> 0
A11: (−) Amortização | B11: R$ mi | D11: =IF(D6=1,MIN(D9+D10,MAX(0,D7-D13)),0) -> 0 | E11: =IF(E6=1,MIN(E9+E10,MAX(0,E7-E13)),0) -> 0 | F11: =IF(F6=1,MIN(F9+F10,MAX(0,F7-F13)),0) -> 0 | G11: =IF(G6=1,MIN(G9+G10,MAX(0,G7-G13)),0) -> 0 | H11: =IF(H6=1,MIN(H9+H10,MAX(0,H7-H13)),0) -> 0 | I11: =IF(I6=1,MIN(I9+I10,MAX(0,I7-I13)),0) -> 0 | J11: =IF(J6=1,MIN(J9+J10,MAX(0,J7-J13)),0) -> 0 | K11: =IF(K6=1,MIN(K9+K10,MAX(0,K7-K13)),0) -> 0 | ... AG11: =IF(AG6=1,MIN(AG9+AG10,MAX(0,AG7-AG13)),0) -> 0
A12: Saldo final | B12: R$ mi | D12: =D9+D10-D11 -> 292.16873 | E12: =E9+E10-E11 -> 588.14258 | F12: =F9+F10-F11 -> 2113.3388 | G12: =G9+G10-G11 -> 3295.3298 | H12: =H9+H10-H11 -> 4418.5023 | I12: =I9+I10-I11 -> 5303.044 | J12: =J9+J10-J11 -> 5996.5852 | K12: =K9+K10-K11 -> 6643.4238 | ... AG12: =AG9+AG10-AG11 -> 0
A13: Juros | B13: R$ mi | D13: =D9*$C$17 -> 0 | E13: =E9*$C$17 -> 22.789161 | F13: =F9*$C$17 -> 45.875121 | G13: =G9*$C$17 -> 164.84043 | H13: =H9*$C$17 -> 257.03572 | I13: =I9*$C$17 -> 344.64318 | J13: =J9*$C$17 -> 413.63743 | K13: =K9*$C$17 -> 467.73365 | ... AG13: =AG9*$C$17 -> 0
A14: Serviço da dívida (juros + amortização) | B14: R$ mi | D14: =D13+D11 -> 0 | E14: =E13+E11 -> 22.789161 | F14: =F13+F11 -> 45.875121 | G14: =G13+G11 -> 164.84043 | H14: =H13+H11 -> 257.03572 | I14: =I13+I11 -> 344.64318 | J14: =J13+J11 -> 413.63743 | K14: =K13+K11 -> 467.73365 | ... AG14: =AG13+AG11 -> 0
A15: ICSD | B15: x | D15: =IF(D14>0,'5. Caixa'!D15/D14,"") | E15: =IF(E14>0,'5. Caixa'!E15/E14,"") -> 12.720577 | F15: =IF(F14>0,'5. Caixa'!F15/F14,"") -> 8.3725318 | G15: =IF(G14>0,'5. Caixa'!G15/G14,"") -> 2.979762 | H15: =IF(H14>0,'5. Caixa'!H15/H14,"") -> 2.1101192 | I15: =IF(I14>0,'5. Caixa'!I15/I14,"") -> 1.7175422 | J15: =IF(J14>0,'5. Caixa'!J15/J14,"") -> 1.5323461 | K15: =IF(K14>0,'5. Caixa'!K15/K14,"") -> 1.437612 | ... AG15: =IF(AG14>0,'5. Caixa'!AG15/AG14,"")
A17: Custo da dívida no cenário | C17: ='1. Premissas'!$B$16+'2. Cenários'!$E$8 -> 0.078
A18: Capacidade de dívida (VP do serviço máximo) | C18: =NPV(C17,D7:AG7)*(1+C17)^('1. Premissas'!$B$18-1) -> 6643.4238
A19: Capex da construção | C19: =SUMIF(D4:AG4,"<"&'1. Premissas'!$B$18,'4. Custos'!D10:AG10) -> 10527.884
A20: Alavancagem usada | C20: =MIN('1. Premissas'!$B$20,C18/C19) -> 0.63103125
A21: Dívida total | C21: =C20*C19 -> 6643.4238

Sheet 7. Retornos
A1: 7. Retornos
A2: Fluxo do acionista e TIRs. O desconto máximo sai do Atingir Meta (TIR do equity = hurdle).
A4: Ano da concessão | B4: Unidade | C4: Total | D4: 1 | E4: 2 | F4: 3 | G4: 4 | H4: 5 | I4: 6 | J4: 7 | K4: 8 | L4: 9 | M4: 10 | N4: 11 | O4: 12 | P4: 13 | Q4: 14 | R4: 15 | S4: 16 | T4: 17 | U4: 18 | V4: 19 | W4: 20 | X4: 21 | Y4: 22 | Z4: 23 | AA4: 24 | AB4: 25 | AC4: 26 | AD4: 27 | AE4: 28 | AF4: 29 | AG4: 30
A5: FLUXOS
A6: Fluxo do projeto | B6: R$ mi | D6: ='5. Caixa'!D17 -> -399.04846 | E6: ='5. Caixa'!E17 -> -179.14072 | F6: ='5. Caixa'!F17 -> -2032.8991 | G6: ='5. Caixa'!G17 -> -1381.9248 | H6: ='5. Caixa'!H17 -> -1237.524 | I6: ='5. Caixa'!I17 -> -809.80081 | J6: ='5. Caixa'!J17 -> -465.22429 | K6: ='5. Caixa'!K17 -> -352.6305 | ... AG6: ='5. Caixa'!AG17 -> 1878.9836
A7: (+) Captação de dívida | B7: R$ mi | D7: ='6. Dívida'!D10 -> 292.16873 | E7: ='6. Dívida'!E10 -> 295.97385 | F7: ='6. Dívida'!F10 -> 1525.1962 | G7: ='6. Dívida'!G10 -> 1181.9909 | H7: ='6. Dívida'!H10 -> 1123.1725 | I7: ='6. Dívida'!I10 -> 884.54175 | J7: ='6. Dívida'!J10 -> 693.54121 | K7: ='6. Dívida'!K10 -> 646.83858 | ... AG7: ='6. Dívida'!AG10 -> 0
A8: (−) Serviço da dívida | B8: R$ mi | D8: =-'6. Dívida'!D14 -> 0 | E8: =-'6. Dívida'!E14 -> -22.789161 | F8: =-'6. Dívida'!F14 -> -45.875121 | G8: =-'6. Dívida'!G14 -> -164.84043 | H8: =-'6. Dívida'!H14 -> -257.03572 | I8: =-'6. Dívida'!I14 -> -344.64318 | J8: =-'6. Dívida'!J14 -> -413.63743 | K8: =-'6. Dívida'!K14 -> -467.73365 | ... AG8: =-'6. Dívida'!AG14 -> 0
A9: (+) Benefício fiscal dos juros | B9: R$ mi | D9: =MIN('6. Dívida'!D13,MAX(0,'5. Caixa'!D11))*'1. Premissas'!$B$13 -> 0 | E9: =MIN('6. Dívida'!E13,MAX(0,'5. Caixa'!E11))*'1. Premissas'!$B$13 -> 7.7483148 | F9: =MIN('6. Dívida'!F13,MAX(0,'5. Caixa'!F11))*'1. Premissas'!$B$13 -> 15.597541 | G9: =MIN('6. Dívida'!G13,MAX(0,'5. Caixa'!G11))*'1. Premissas'!$B$13 -> 56.045745 | H9: =MIN('6. Dívida'!H13,MAX(0,'5. Caixa'!H11))*'1. Premissas'!$B$13 -> 87.392145 | I9: =MIN('6. Dívida'!I13,MAX(0,'5. Caixa'!I11))*'1. Premissas'!$B$13 -> 117.17868 | J9: =MIN('6. Dívida'!J13,MAX(0,'5. Caixa'!J11))*'1. Premissas'!$B$13 -> 140.63673 | K9: =MIN('6. Dívida'!K13,MAX(0,'5. Caixa'!K11))*'1. Premissas'!$B$13 -> 159.02944 | ... AG9: =MIN('6. Dívida'!AG13,MAX(0,'5. Caixa'!AG11))*'1. Premissas'!$B$13 -> 0
A10: Fluxo antes do lock-up | B10: R$ mi | D10: =SUM(D6:D9) -> -106.87973 | E10: =SUM(E6:E9) -> 101.79228 | F10: =SUM(F6:F9) -> -537.98044 | G10: =SUM(G6:G9) -> -308.7285 | H10: =SUM(H6:H9) -> -283.99505 | I10: =SUM(I6:I9) -> -152.72356 | J10: =SUM(J6:J9) -> -44.683793 | K10: =SUM(K6:K9) -> -14.496124 | ... AG10: =SUM(AG6:AG9) -> 1878.9836
A11: (−) Caixa retido na obra | B11: R$ mi | D11: =IF(D$4<'1. Premissas'!$B$18,-MAX(0,D10),0) -> 0 | E11: =IF(E$4<'1. Premissas'!$B$18,-MAX(0,E10),0) -> -101.79228 | F11: =IF(F$4<'1. Premissas'!$B$18,-MAX(0,F10),0) -> 0 | G11: =IF(G$4<'1. Premissas'!$B$18,-MAX(0,G10),0) -> 0 | H11: =IF(H$4<'1. Premissas'!$B$18,-MAX(0,H10),0) -> 0 | I11: =IF(I$4<'1. Premissas'!$B$18,-MAX(0,I10),0) -> 0 | J11: =IF(J$4<'1. Premissas'!$B$18,-MAX(0,J10),0) -> 0 | K11: =IF(K$4<'1. Premissas'!$B$18,-MAX(0,K10),0) -> 0 | ... AG11: =IF(AG$4<'1. Premissas'!$B$18,-MAX(0,AG10),0) -> 0
A12: (+) Liberação do caixa retido | B12: R$ mi | D12: =IF(D$4='1. Premissas'!$B$18,-SUM($D$11:D11),0) -> 0 | E12: =IF(E$4='1. Premissas'!$B$18,-SUM($D$11:E11),0) -> 0 | F12: =IF(F$4='1. Premissas'!$B$18,-SUM($D$11:F11),0) -> 0 | G12: =IF(G$4='1. Premissas'!$B$18,-SUM($D$11:G11),0) -> 0 | H12: =IF(H$4='1. Premissas'!$B$18,-SUM($D$11:H11),0) -> 0 | I12: =IF(I$4='1. Premissas'!$B$18,-SUM($D$11:I11),0) -> 0 | J12: =IF(J$4='1. Premissas'!$B$18,-SUM($D$11:J11),0) -> 0 | K12: =IF(K$4='1. Premissas'!$B$18,-SUM($D$11:K11),0) -> 0 | ... AG12: =IF(AG$4='1. Premissas'!$B$18,-SUM($D$11:AG11),0) -> 0
A13: Fluxo do acionista | B13: R$ mi | D13: =D10+D11+D12 -> -106.87973 | E13: =E10+E11+E12 -> 0 | F13: =F10+F11+F12 -> -537.98044 | G13: =G10+G11+G12 -> -308.7285 | H13: =H10+H11+H12 -> -283.99505 | I13: =I10+I11+I12 -> -152.72356 | J13: =J10+J11+J12 -> -44.683793 | K13: =K10+K11+K12 -> -14.496124 | ... AG13: =AG10+AG11+AG12 -> 1878.9836
A14: RESULTADOS (só na coluna C)
A15: TIR do projeto | B15: R$ mi | C15: =IRR('5. Caixa'!D17:AG17) -> 0.077117609
A16: TIR do acionista | B16: R$ mi | C16: =IRR(D13:AG13) -> 0.12005201
A17: VPL do acionista no hurdle | B17: R$ mi | C17: =NPV('1. Premissas'!$B$22,D13:AG13) -> 0.68054673

Sheet 8. Sensibilidades
A1: 8. Sensibilidades
A2: Retorno do acionista para cada desconto ofertado, por cenário.
A3: Tabela viva: aba 1, linhas 29-39. Abaixo, cópia em valores (cenário base: desconto 25,2%, hurdle 12%)
A5: Desconto | B5: Base | C5: Pessimista | D5: Otimista | E5: Hurdle
A6: 0 | B6: 0.43769205 | C6: 0.12904883 | D6: 0.65141422 | E6: 0.12
A7: 0.05 | B7: 0.35644292 | C7: 0.10370182 | D7: 0.54652691 | E7: 0.12
A8: 0.1 | B8: 0.28583102 | C8: 0.083937601 | D8: 0.44226504 | E8: 0.12
A9: 0.15 | B9: 0.23389196 | C9: 0.067587585 | D9: 0.35624119 | E9: 0.12
A10: 0.2 | B10: 0.17124676 | C10: 0.05325005 | D10: 0.28133646 | E10: 0.12
A11: 0.25 | B11: 0.12221584 | C11: 0.04038261 | D11: 0.22538257 | E11: 0.12
A12: 0.3 | B12: 0.090582167 | C12: 0.02862203 | D12: 0.18128439 | E12: 0.12
A13: 0.35 | B13: 0.067269516 | C13: 0.017373489 | D13: 0.12086581 | E13: 0.12
A14: 0.4 | B14: 0.048017359 | C14: 0.0063323551 | D14: 0.084026681 | E14: 0.12

Sheet 9. Checagens
A1: 9. Checagens
A2: (ao longo do caminho) Ex.: com desconto 0%, a TIR do projeto precisa dar ~12,49%.
A4: Teste | B4: Valor | C4: OK?
A5: Dívida quitada no fim | B5: ='6. Dívida'!AG12 -> 0 | C5: =ABS(B5)<0.01 -> TRUE
A6: Toda a dívida captada | B6: =SUM('6. Dívida'!D10:AG10)-'6. Dívida'!C21 -> 0 | C6: =ABS(B6)<0.01 -> TRUE
A7: ICSD mínimo na amortização | B7: =MIN('6. Dívida'!L15:AA15) -> 1.3 | C7: =B7>='1. Premissas'!B17-0.001 -> TRUE
A8: Caixa retido todo liberado | B8: =SUM('7. Retornos'!D11:AG12) -> 0 | C8: =ABS(B8)<0.01 -> TRUE
A9: Capex igual ao MEF × cenário | B9: =SUM('4. Custos'!D10:AG10)-SUM(Dados_MEF!D40:AG40)*'2. Cenários'!E6 -> 0 | C9: =ABS(B9)<0.01 -> TRUE
A10: TUDO OK? | C10: =AND(C5:C9) -> TRUE
